Workbook

Sheet Data
A1: Order ID | B1: Order Date | C1: Order Time | D1: Restaurant | E1: City | F1: Cuisine | G1: Delivery Partner | H1: Distance (km) | I1: Delivery Time | J1: Estimated Time | K1: Order Value | L1: Delivery Fee | M1: Discount | N1: Payment Mode | O1: Customer Rating | P1: Order Status | Q1: Customer Gender | R1: Customer Age | S1: Weekday | T1: Peak Hour | U1: Year | V1: Month | W1: Month Name | X1: Quarter | Y1: Day | Z1: Week of Month | AA1: Hour | AB1: food time | AC1: final revenue | AD1: delivery speed | AE1: customer performance | AF1: age group | AG1: delay | AH1: late or on time | AI1: FilterFlag
A2: ORD00001 | B2: 46066 | C2: -0.65555556 | D2: McDonald's | E2: Mysore | F2: South Indian | G2: Shadowfax | H2: 11.5 | I2: 38 | J2: 41 | K2: 247 | L2: 30 | M2: 164 | N2: Cash | O2: 4 | P2: Delivered | Q2: Female | R2: 39 | S2: Friday | T2: Breakfast | U2: 2026 | V2: 2 | W2: February | X2: 1 | Y2: 13 | Z2: 3 | AA2: 8 | AB2: Breakfast | AC2: 113 | AD2: 0.30263158 | AE2: good | AF2: older | AG2: -3 | AH2: on time | AI2: =--AND(OR(Dashboard!$B$4="All",Data!$E2=Dashboard!$B$4),OR(Dashboard!$D$4="All",Data!$D2=Dashboard!$D$4),OR(Dashboard!$F$4="All",Data!$F2=Dashboard!$F$4),OR(Dashboard!$J$4="All",Data!$G2=Dashboard!$J$4),OR(Dashboard!$H$4="All",Data!$N2=Dashboard!$H$4),OR(Dashboard!$L$4="All",Data!$W2=Dashboard!$L$4)) -> 1
A3: ORD00002 | B3: 46071 | C3: -0.2375 | D3: Barbeque Nation | E3: Pune | F3: Beverages | G3: Zomato Fleet | H3: 13.2 | I3: 27 | J3: 32 | K3: 705 | L3: 53 | M3: 82 | N3: Credit Card | O3: 2 | P3: Delivered | Q3: Female | R3: 47 | S3: Wednesday | T3: Dinner | U3: 2026 | V3: 2 | W3: February | X3: 1 | Y3: 18 | Z3: 4 | AA3: 18 | AB3: snacks | AC3: 676 | AD3: 0.48888889 | AE3: poor | AF3: senior | AG3: -5 | AH3: on time | AI3: =--AND(OR(Dashboard!$B$4="All",Data!$E3=Dashboard!$B$4),OR(Dashboard!$D$4="All",Data!$D3=Dashboard!$D$4),OR(Dashboard!$F$4="All",Data!$F3=Dashboard!$F$4),OR(Dashboard!$J$4="All",Data!$G3=Dashboard!$J$4),OR(Dashboard!$H$4="All",Data!$N3=Dashboard!$H$4),OR(Dashboard!$L$4="All",Data!$W3=Dashboard!$L$4)) -> 1
A4: ORD00003 | B4: 46094 | C4: -0.25 | D4: Meghana Foods | E4: Bangalore | F4: North Indian | G4: Blinkit Express | H4: 5.3 | I4: 42 | J4: 37 | K4: 1000 | L4: 57 | M4: 180 | N4: UPI | O4: 1 | P4: Delivered | Q4: Female | R4: 33 | S4: Friday | T4: Dinner | U4: 2026 | V4: 3 | W4: March | X4: 1 | Y4: 13 | Z4: 3 | AA4: 18 | AB4: snacks | AC4: 877 | AD4: 0.12619048 | AE4: poor | AF4: adult | AG4: 5 | AH4: late | AI4: =--AND(OR(Dashboard!$B$4="All",Data!$E4=Dashboard!$B$4),OR(Dashboard!$D$4="All",Data!$D4=Dashboard!$D$4),OR(Dashboard!$F$4="All",Data!$F4=Dashboard!$F$4),OR(Dashboard!$J$4="All",Data!$G4=Dashboard!$J$4),OR(Dashboard!$H$4="All",Data!$N4=Dashboard!$H$4),OR(Dashboard!$L$4="All",Data!$W4=Dashboard!$L$4)) -> 1
A5: ORD00004 | B5: 46083 | C5: -0.53611111 | D5: Burger King | E5: Delhi | F5: Burger | G5: Blinkit Express | H5: 2.4 | I5: 27 | J5: 29 | K5: 824 | L5: 55 | M5: 52 | N5: Cash | O5: 5 | P5: Delivered | Q5: Male | R5: 43 | S5: Monday | T5: Late Night | U5: 2026 | V5: 3 | W5: March | X5: 1 | Y5: 2 | Z5: 2 | AA5: 11 | AB5: lunch | AC5: 827 | AD5: 0.088888889 | AE5: excellent | AF5: older | AG5: -2 | AH5: on time | AI5: =--AND(OR(Dashboard!$B$4="All",Data!$E5=Dashboard!$B$4),OR(Dashboard!$D$4="All",Data!$D5=Dashboard!$D$4),OR(Dashboard!$F$4="All",Data!$F5=Dashboard!$F$4),OR(Dashboard!$J$4="All",Data!$G5=Dashboard!$J$4),OR(Dashboard!$H$4="All",Data!$N5=Dashboard!$H$4),OR(Dashboard!$L$4="All",Data!$W5=Dashboard!$L$4)) -> 1
A6: ORD00005 | B6: 46060 | C6: -0.16527778 | D6: Faasos | E6: Delhi | F6: Fast Food | G6: Zomato Fleet | H6: 8.7 | I6: 44 | J6: 40 | K6: 1083 | L6: 24 | M6: 68 | N6: Credit Card | O6: 4 | P6: Delivered | Q6: Female | R6: 30 | S6: Saturday | T6: Dinner | U6: 2026 | V6: 2 | W6: February | X6: 1 | Y6: 7 | Z6: 2 | AA6: 20 | AB6: dinner | AC6: 1039 | AD6: 0.19772727 | AE6: good | AF6: adult | AG6: 4 | AH6: late | AI6: =--AND(OR(Dashboard!$B$4="All",Data!$E6=Dashboard!$B$4),OR(Dashboard!$D$4="All",Data!$D6=Dashboard!$D$4),OR(Dashboard!$F$4="All",Data!$F6=Dashboard!$F$4),OR(Dashboard!$J$4="All",Data!$G6=Dashboard!$J$4),OR(Dashboard!$H$4="All",Data!$N6=Dashboard!$H$4),OR(Dashboard!$L$4="All",Data!$W6=Dashboard!$L$4)) -> 1
A7: ORD00006 | B7: 46170 | C7: -0.60763889 | D7: Behrouz Biryani | E7: Delhi | F7: Desserts | G7: Shadowfax | H7: 5.1 | I7: 59 | J7: 40 | K7: 1060 | L7: 39 | M7: 109 | N7: Debit Card | O7: 1 | P7: Delivered | Q7: Male | R7: 41 | S7: Thursday | T7: Breakfast | U7: 2026 | V7: 5 | W7: May | X7: 2 | Y7: 28 | Z7: 5 | AA7: 9 | AB7: Breakfast | AC7: 990 | AD7: 0.086440678 | AE7: poor | AF7: older | AG7: 19 | AH7: late | AI7: =--AND(OR(Dashboard!$B$4="All",Data!$E7=Dashboard!$B$4),OR(Dashboard!$D$4="All",Data!$D7=Dashboard!$D$4),OR(Dashboard!$F$4="All",Data!$F7=Dashboard!$F$4),OR(Dashboard!$J$4="All",Data!$G7=Dashboard!$J$4),OR(Dashboard!$H$4="All",Data!$N7=Dashboard!$H$4),OR(Dashboard!$L$4="All",Data!$W7=Dashboard!$L$4)) -> 1
A8: ORD00007 | B8: 46169 | C8: -0.18402778 | D8: Domino's | E8: Pune | F8: Biryani | G8: Zomato Fleet | H8: 8.6 | I8: 35 | J8: 30 | K8: 1029 | L8: 35 | M8: 125 | N8: Credit Card | O8: 5 | P8: Delivered | Q8: Female | R8: 48 | S8: Wednesday | T8: Dinner | U8: 2026 | V8: 5 | W8: May | X8: 2 | Y8: 27 | Z8: 5 | AA8: 19 | AB8: dinner | AC8: 939 | AD8: 0.24571429 | AE8: excellent | AF8: senior | AG8: 5 | AH8: late | AI8: =--AND(OR(Dashboard!$B$4="All",Data!$E8=Dashboard!$B$4),OR(Dashboard!$D$4="All",Data!$D8=Dashboard!$D$4),OR(Dashboard!$F$4="All",Data!$F8=Dashboard!$F$4),OR(Dashboard!$J$4="All",Data!$G8=Dashboard!$J$4),OR(Dashboard!$H$4="All",Data!$N8=Dashboard!$H$4),OR(Dashboard!$L$4="All",Data!$W8=Dashboard!$L$4)) -> 1
A9: ORD00008 | B9: 46164 | C9: -0.025 | D9: Behrouz Biryani | E9: Bangalore | F9: North Indian | G9: Shadowfax | H9: 11 | I9: 32 | J9: 23 | K9: 815 | L9: 28 | M9: 28 | N9: Debit Card | O9: 4 | P9: Delivered | Q9: Female | R9: 58 | S9: Friday | T9: Late Night | U9: 2026 | V9: 5 | W9: May | X9: 2 | Y9: 22 | Z9: 4 | AA9: 23 | AB9: late night | AC9: 815 | AD9: 0.34375 | AE9: good | AF9: senior | AG9: 9 | AH9: late | AI9: =--AND(OR(Dashboard!$B$4="All",Data!$E9=Dashboard!$B$4),OR(Dashboard!$D$4="All",Data!$D9=Dashboard!$D$4),OR(Dashboard!$F$4="All",Data!$F9=Dashboard!$F$4),OR(Dashboard!$J$4="All",Data!$G9=Dashboard!$J$4),OR(Dashboard!$H$4="All",Data!$N9=Dashboard!$H$4),OR(Dashboard!$L$4="All",Data!$W9=Dashboard!$L$4)) -> 1
A10: ORD00009 | B10: 46167 | C10: -0.42986111 | D10: McDonald's | E10: Kochi | F10: Seafood | G10: Shadowfax | H10: 9.3 | I10: 45 | J10: 28 | K10: 990 | L10: 49 | M10: 111 | N10: Cash | O10: 1 | P10: Delivered | Q10: Female | R10: 53 | S10: Monday | T10: Lunch | U10: 2026 | V10: 5 | W10: May | X10: 2 | Y10: 25 | Z10: 5 | AA10: 13 | AB10: lunch | AC10: 928 | AD10: 0.20666667 | AE10: poor | AF10: senior | AG10: 17 | AH10: late | AI10: =--AND(OR(Dashboard!$B$4="All",Data!$E10=Dashboard!$B$4),OR(Dashboard!$D$4="All",Data!$D10=Dashboard!$D$4),OR(Dashboard!$F$4="All",Data!$F10=Dashboard!$F$4),OR(Dashboard!$J$4="All",Data!$G10=Dashboard!$J$4),OR(Dashboard!$H$4="All",Data!$N10=Dashboard!$H$4),OR(Dashboard!$L$4="All",Data!$W10=Dashboard!$L$4)) -> 1
A11: ORD00010 | B11: 46041 | C11: -0.6625 | D11: Haldiram's | E11: Coimbatore | F11: South Indian | G11: Zomato Fleet | H11: 12.9 | I11: 63 | J11: 43 | K11: 961 | L11: 27 | M11: 151 | N11: Wallet | O11: 2 | P11: Delivered | Q11: Male | R11: 58 | S11: Monday | T11: Breakfast | U11: 2026 | V11: 1 | W11: January | X11: 1 | Y11: 19 | Z11: 4 | AA11: 8 | AB11: Breakfast | AC11: 837 | AD11: 0.2047619 | AE11: poor | AF11: senior | AG11: 20 | AH11: late | AI11: =--AND(OR(Dashboard!$B$4="All",Data!$E11=Dashboard!$B$4),OR(Dashboard!$D$4="All",Data!$D11=Dashboard!$D$4),OR(Dashboard!$F$4="All",Data!$F11=Dashboard!$F$4),OR(Dashboard!$J$4="All",Data!$G11=Dashboard!$J$4),OR(Dashboard!$H$4="All",Data!$N11=Dashboard!$H$4),OR(Dashboard!$L$4="All",Data!$W11=Dashboard!$L$4)) -> 1
A12: ORD00011 | B12: 46080 | C12: -0.49722222 | D12: Barbeque Nation | E12: Mysore | F12: Pizza | G12: Dunzo | H12: 9 | I12: 45 | J12: 28 | K12: 247 | L12: 46 | M12: 117 | N12: Credit Card | O12: 5 | P12: Delivered | Q12: Female | R12: 60 | S12: Friday | T12: Lunch | U12: 2026 | V12: 2 | W12: February | X12: 1 | Y12: 27 | Z12: 5 | AA12: 12 | AB12: lunch | AC12: 176 | AD12: 0.2 | AE12: excellent | AF12: senior | AG12: 17 | AH12: late | AI12: =--AND(OR(Dashboard!$B$4="All",Data!$E12=Dashboard!$B$4),OR(Dashboard!$D$4="All",Data!$D12=Dashboard!$D$4),OR(Dashboard!$F$4="All",Data!$F12=Dashboard!$F$4),OR(Dashboard!$J$4="All",Data!$G12=Dashboard!$J$4),OR(Dashboard!$H$4="All",Data!$N12=Dashboard!$H$4),OR(Dashboard!$L$4="All",Data!$W12=Dashboard!$L$4)) -> 1
A13: ORD00012 | B13: 46060 | C13: -0.44861111 | D13: Saravana Bhavan | E13: Kolkata | F13: Burger | G13: Blinkit Express | H13: 10.6 | I13: 38 | J13: 42 | K13: 750 | L13: 35 | M13: 10 | N13: Credit Card | O13: 3 | P13: Delivered | Q13: Male | R13: 34 | S13: Saturday | T13: Lunch | U13: 2026 | V13: 2 | W13: February | X13: 1 | Y13: 7 | Z13: 2 | AA13: 13 | AB13: lunch | AC13: 775 | AD13: 0.27894737 | AE13: average | AF13: adult | AG13: -4 | AH13: on time | AI13: =--AND(OR(Dashboard!$B$4="All",Data!$E13=Dashboard!$B$4),OR(Dashboard!$D$4="All",Data!$D13=Dashboard!$D$4),OR(Dashboard!$F$4="All",Data!$F13=Dashboard!$F$4),OR(Dashboard!$J$4="All",Data!$G13=Dashboard!$J$4),OR(Dashboard!$H$4="All",Data!$N13=Dashboard!$H$4),OR(Dashboard!$L$4="All",Data!$W13=Dashboard!$L$4)) -> 1
... A5001: ORD05000 | B5001: 46140 | C5001: -0.26111111 | D5001: Saravana Bhavan | E5001: Mysore | F5001: Desserts | G5001: Rapido Delivery | H5001: 12.6 | I5001: 38 | J5001: 31 | K5001: 834 | L5001: 43 | M5001: 11 | N5001: Credit Card | O5001: 1 | P5001: Cancelled | Q5001: Female | R5001: 45 | S5001: Tuesday | T5001: Late Night | U5001: 2026 | V5001: 4 | W5001: April | X5001: 2 | Y5001: 28 | Z5001: 5 | AA5001: 17 | AB5001: snacks | AC5001: 866 | AD5001: 0.33157895 | AE5001: poor | AF5001: older | AG5001: 7 | AH5001: late | AI5001: =--AND(OR(Dashboard!$B$4="All",Data!$E5001=Dashboard!$B$4),OR(Dashboard!$D$4="All",Data!$D5001=Dashboard!$D$4),OR(Dashboard!$F$4="All",Data!$F5001=Dashboard!$F$4),OR(Dashboard!$J$4="All",Data!$G5001=Dashboard!$J$4),OR(Dashboard!$H$4="All",Data!$N5001=Dashboard!$H$4),OR(Dashboard!$L$4="All",Data!$W5001=Dashboard!$L$4)) -> 1

Sheet Lists
A1: All | B1: All | C1: All | D1: All | E1: All | F1: All
A2: Bangalore | B2: A2B | C2: Beverages | D2: Cash | E2: Blinkit Express | F2: January
A3: Chennai | B3: Barbeque Nation | C3: Biryani | D3: Credit Card | E3: Dunzo | F3: February
A4: Coimbatore | B4: Behrouz Biryani | C4: Burger | D4: Debit Card | E4: Porter | F4: March
A5: Delhi | B5: Burger King | C5: Chinese | D5: UPI | E5: Rapido Delivery | F5: April
A6: Hyderabad | B6: Domino's | C6: Desserts | D6: Wallet | E6: Shadowfax | F6: May
A7: Kochi | B7: Faasos | C7: Fast Food | E7: Zomato Fleet | F7: June
A8: Kolkata | B8: Haldiram's | C8: North Indian
A9: Mumbai | B9: KFC | C9: Pizza
A10: Mysore | B10: McDonald's | C10: Seafood
A11: Pune | B11: Meghana Foods | C11: South Indian
B12: Paradise Biryani
B13: Pizza Hut
B14: Saravana Bhavan
B15: Subway
B16: Wow Momo

Sheet Dashboard
B1: ZOMATO DELIVERY DASHBOARD
B2: Use the dropdown slicers to filter the KPI cards and charts
B3: City | D3: Restaurant | F3: Cuisine | H3: Payment Mode | J3: Delivery Partner | L3: Month
B4: All | D4: All | F4: All | H4: All | J4: All | L4: All
B6: ORDERS | D6: REVENUE | F6: AVG RATING | H6: AVG DELIVERY TIME | J6: CANCELLATION %
B7: =COUNTIFS(Data!$AI$2:$AI$5001,1) -> 5000 | D7: 3055663 | F7: =IFERROR(AVERAGEIFS(Data!$O$2:$O$5001,Data!$AI$2:$AI$5001,1),0) -> 2.9816 | H7: =IFERROR(AVERAGEIFS(Data!$I$2:$I$5001,Data!$AI$2:$AI$5001,1),0) -> 40.2634 | J7: =IFERROR(COUNTIFS(Data!$AI$2:$AI$5001,1,Data!$P$2:$P$5001,"Cancelled")/COUNTIFS(Data!$AI$2:$AI$5001,1),0) -> 0.106
D96: findings and suggestion
B99: Finding 1: Late deliveries are significantly higher → Suggestion: Optimize routes and increase delivery partners during peak hours.
B100: Finding 2: Pune and Chennai have high revenue → Suggestion: Strengthen operations in these cities and promote lower-performing cities.
B101: Finding 3: Average rating is only 2.98 → Suggestion: Improve food quality, delivery speed, and order accuracy.

Sheet Dashboard Data
A1: Revenue by Month
A2: Category | B2: Value
A3: January | B3: =SUMIFS(Data!$AH$2:$AH$5001,Data!$AI$2:$AI$5001,1,Data!$W$2:$W$5001,A3) -> 0
A4: February | B4: =SUMIFS(Data!$AH$2:$AH$5001,Data!$AI$2:$AI$5001,1,Data!$W$2:$W$5001,A4) -> 0
A5: March | B5: =SUMIFS(Data!$AH$2:$AH$5001,Data!$AI$2:$AI$5001,1,Data!$W$2:$W$5001,A5) -> 0
A6: April | B6: =SUMIFS(Data!$AH$2:$AH$5001,Data!$AI$2:$AI$5001,1,Data!$W$2:$W$5001,A6) -> 0
A7: May | B7: =SUMIFS(Data!$AH$2:$AH$5001,Data!$AI$2:$AI$5001,1,Data!$W$2:$W$5001,A7) -> 0
A8: June | B8: =SUMIFS(Data!$AH$2:$AH$5001,Data!$AI$2:$AI$5001,1,Data!$W$2:$W$5001,A8) -> 0
A11: Revenue by City
A12: Category | B12: Value
A13: Bangalore | B13: =SUMIFS(Data!$AH$2:$AH$5001,Data!$AI$2:$AI$5001,1,Data!$E$2:$E$5001,A13) -> 0
A14: Chennai | B14: =SUMIFS(Data!$AH$2:$AH$5001,Data!$AI$2:$AI$5001,1,Data!$E$2:$E$5001,A14) -> 0
A15: Coimbatore | B15: =SUMIFS(Data!$AH$2:$AH$5001,Data!$AI$2:$AI$5001,1,Data!$E$2:$E$5001,A15) -> 0
A16: Delhi | B16: =SUMIFS(Data!$AH$2:$AH$5001,Data!$AI$2:$AI$5001,1,Data!$E$2:$E$5001,A16) -> 0
A17: Hyderabad | B17: =SUMIFS(Data!$AH$2:$AH$5001,Data!$AI$2:$AI$5001,1,Data!$E$2:$E$5001,A17) -> 0
A18: Kochi | B18: =SUMIFS(Data!$AH$2:$AH$5001,Data!$AI$2:$AI$5001,1,Data!$E$2:$E$5001,A18) -> 0
A19: Kolkata | B19: =SUMIFS(Data!$AH$2:$AH$5001,Data!$AI$2:$AI$5001,1,Data!$E$2:$E$5001,A19) -> 0
A20: Mumbai | B20: =SUMIFS(Data!$AH$2:$AH$5001,Data!$AI$2:$AI$5001,1,Data!$E$2:$E$5001,A20) -> 0
A21: Mysore | B21: =SUMIFS(Data!$AH$2:$AH$5001,Data!$AI$2:$AI$5001,1,Data!$E$2:$E$5001,A21) -> 0
A22: Pune | B22: =SUMIFS(Data!$AH$2:$AH$5001,Data!$AI$2:$AI$5001,1,Data!$E$2:$E$5001,A22) -> 0
A25: Cuisine Sales
A26: Category | B26: Value
A27: Beverages | B27: =SUMIFS(Data!$AH$2:$AH$5001,Data!$AI$2:$AI$5001,1,Data!$F$2:$F$5001,A27) -> 0
A28: Biryani | B28: =SUMIFS(Data!$AH$2:$AH$5001,Data!$AI$2:$AI$5001,1,Data!$F$2:$F$5001,A28) -> 0
A29: Burger | B29: =SUMIFS(Data!$AH$2:$AH$5001,Data!$AI$2:$AI$5001,1,Data!$F$2:$F$5001,A29) -> 0
A30: Chinese | B30: =SUMIFS(Data!$AH$2:$AH$5001,Data!$AI$2:$AI$5001,1,Data!$F$2:$F$5001,A30) -> 0
A31: Desserts | B31: =SUMIFS(Data!$AH$2:$AH$5001,Data!$AI$2:$AI$5001,1,Data!$F$2:$F$5001,A31) -> 0
A32: Fast Food | B32: =SUMIFS(Data!$AH$2:$AH$5001,Data!$AI$2:$AI$5001,1,Data!$F$2:$F$5001,A32) -> 0
A33: North Indian | B33: =SUMIFS(Data!$AH$2:$AH$5001,Data!$AI$2:$AI$5001,1,Data!$F$2:$F$5001,A33) -> 0
A34: Pizza | B34: =SUMIFS(Data!$AH$2:$AH$5001,Data!$AI$2:$AI$5001,1,Data!$F$2:$F$5001,A34) -> 0
A35: Seafood | B35: =SUMIFS(Data!$AH$2:$AH$5001,Data!$AI$2:$AI$5001,1,Data!$F$2:$F$5001,A35) -> 0
A36: South Indian | B36: =SUMIFS(Data!$AH$2:$AH$5001,Data!$AI$2:$AI$5001,1,Data!$F$2:$F$5001,A36) -> 0
A39: Partner Performance
A40: Category | B40: Value
A41: Blinkit Express | B41: =SUMIFS(Data!$AH$2:$AH$5001,Data!$AI$2:$AI$5001,1,Data!$G$2:$G$5001,A41) -> 0
A42: Dunzo | B42: =SUMIFS(Data!$AH$2:$AH$5001,Data!$AI$2:$AI$5001,1,Data!$G$2:$G$5001,A42) -> 0
A43: Porter | B43: =SUMIFS(Data!$AH$2:$AH$5001,Data!$AI$2:$AI$5001,1,Data!$G$2:$G$5001,A43) -> 0
A44: Rapido Delivery | B44: =SUMIFS(Data!$AH$2:$AH$5001,Data!$AI$2:$AI$5001,1,Data!$G$2:$G$5001,A44) -> 0
A45: Shadowfax | B45: =SUMIFS(Data!$AH$2:$AH$5001,Data!$AI$2:$AI$5001,1,Data!$G$2:$G$5001,A45) -> 0
A46: Zomato Fleet | B46: =SUMIFS(Data!$AH$2:$AH$5001,Data!$AI$2:$AI$5001,1,Data!$G$2:$G$5001,A46) -> 0
...
